Workbook
Name Slicer_Diabetese_Status: #N/A
Name Slicer_Weight_Status: #N/A

Sheet Customer Names
A1: Customer ID | B1: name
A2: Id1 | B2: Hawks, Ms. Kelly
A3: Id2 | B3: Lehner, Mr. Matthew D
A4: Id3 | B4: Lu, Mr. Phil
A5: Id4 | B5: Osborne, Ms. Kelsey
A6: Id5 | B6: Kadala, Ms. Kristyn
A7: Id6 | B7: Baker, Mr. Russell B.
A8: Id7 | B8: Macpherson, Mr. Scott
A9: Id8 | B9: Hallman, Mr. Stephen
A10: Id9 | B10: Moran, Mr. Patrick R.
A11: Id10 | B11: Benner, Ms. Brooke N.
A12: Id11 | B12: Fierro Vargas, Ms. Paola Andrea
... A2336: Id2335 | B2336: German, Mr. Aaron K

Sheet Medical Examinations
A1: Customer ID | B1: BMI | C1: HBA1C | D1: Heart Issues | E1: Any Transplants | F1: Cancer history | G1: NumberOfMajorSurgeries | H1: smoker
A2: Id1 | B2: 47.41 | C2: 7.47 | D2: No | E2: No | F2: No | G2: No major surgery | H2: yes
A3: Id2 | B3: 30.36 | C3: 5.77 | D3: No | E3: No | F3: No | G3: No major surgery | H3: yes
A4: Id3 | B4: 34.485 | C4: 11.87 | D4: yes | E4: No | F4: No | G4: 2 | H4: yes
A5: Id4 | B5: 38.095 | C5: 6.05 | D5: No | E5: No | F5: No | G5: No major surgery | H5: yes
A6: Id5 | B6: 35.53 | C6: 5.45 | D6: No | E6: No | F6: No | G6: No major surgery | H6: yes
A7: Id6 | B7: 32.8 | C7: 6.59 | D7: No | E7: No | F7: No | G7: No major surgery | H7: yes
A8: Id7 | B8: 36.4 | C8: 6.07 | D8: No | E8: No | F8: No | G8: No major surgery | H8: yes
A9: Id8 | B9: 36.96 | C9: 7.93 | D9: No | E9: No | F9: No | G9: 3 | H9: yes
A10: Id9 | B10: 41.14 | C10: 9.58 | D10: yes | E10: No | F10: Yes | G10: 1 | H10: yes
A11: Id10 | B11: 38.06 | C11: 10.79 | D11: No | E11: No | F11: No | G11: No major surgery | H11: yes
A12: Id11 | B12: 37.7 | C12: 5.96 | D12: yes | E12: No | F12: No | G12: 2 | H12: yes
A13: Id12 | B13: 42.13 | C13: 11.9 | D13: No | E13: No | F13: No | G13: No major surgery | H13: yes
A14: Id13 | B14: 40.92 | C14: 8.41 | D14: No | E14: No | F14: No | G14: No major surgery | H14: yes
A15: Id14 | B15: 40.565 | C15: 7.02 | D15: No | E15: No | F15: No | G15: No major surgery | H15: yes
A16: Id15 | B16: 36.385 | C16: 7.59 | D16: yes | E16: No | F16: No | G16: 2 | H16: yes
A17: Id16 | B17: 39.9 | C17: 11.32 | D17: No | E17: No | F17: No | G17: No major surgery | H17: yes
A18: Id17 | B18: 33.8 | C18: 7.67 | D18: No | E18: No | F18: No | G18: 3 | H18: yes
A19: Id18 | B19: 36.765 | C19: 7.29 | D19: yes | E19: No | F19: Yes | G19: 1 | H19: yes
A20: Id19 | B20: 36.955 | C20: 4.72 | D20: yes | E20: No | F20: No | G20: 1 | H20: yes
A21: Id20 | B21: 42.9 | C21: 11.41 | D21: No | E21: No | F21: No | G21: No major surgery | H21: yes
A22: Id21 | B22: 36.3 | C22: 11.5 | D22: yes | E22: No | F22: No | G22: 2 | H22: yes
A23: Id22 | B23: 32.2 | C23: 6.22 | D23: yes | E23: No | F23: No | G23: 2 | H23: yes
A24: Id23 | B24: 31.3 | C24: 11.38 | D24: No | E24: No | F24: No | G24: 3 | H24: yes
A25: Id24 | B25: 41.8 | C25: 7.89 | D25: yes | E25: No | F25: No | G25: 2 | H25: yes
A26: Id25 | B26: 35.09 | C26: 4.38 | D26: yes | E26: No | F26: No | G26: 2 | H26: yes
A27: Id26 | B27: 33.88 | C27: 7.01 | D27: No | E27: No | F27: No | G27: 3 | H27: yes
A28: Id27 | B28: 30.875 | C28: 11.88 | D28: No | E28: No | F28: No | G28: No major surgery | H28: yes
A29: Id28 | B29: 36.86 | C29: 5.19 | D29: yes | E29: No | F29: Yes | G29: 1 | H29: yes
A30: Id29 | B30: 35.86 | C30: 6.74 | D30: yes | E30: No | F30: No | G30: 2 | H30: yes
A31: Id30 | B31: 37.05 | C31: 8.44 | D31: No | E31: No | F31: No | G31: No major surgery | H31: yes
A32: Id31 | B32: 43.89 | C32: 8.71 | D32: No | E32: No | F32: No | G32: No major surgery | H32: yes
A33: Id32 | B33: 42.35 | C33: 5.08 | D33: yes | E33: No | F33: No | G33: No major surgery | H33: yes
A34: Id33 | B34: 31.35 | C34: 6.86 | D34: No | E34: No | F34: No | G34: No major surgery | H34: yes
A35: Id34 | B35: 47.6 | C35: 5.95 | D35: yes | E35: No | F35: No | G35: No major surgery | H35: yes
A36: Id35 | B36: 46.2 | C36: 6.09 | D36: No | E36: No | F36: Yes | G36: 1 | H36: yes
A37: Id36 | B37: 32.015 | C37: 11.75 | D37: No | E37: No | F37: No | G37: No major surgery | H37: yes
A38: Id37 | B38: 40.565 | C38: 7.37 | D38: No | E38: No | F38: No | G38: No major surgery | H38: yes
A39: Id38 | B39: 32.45 | C39: 11.91 | D39: No | E39: No | F39: No | G39: No major surgery | H39: yes
A40: Id39 | B40: 34.96 | C40: 6.52 | D40: No | E40: No | F40: No | G40: No major surgery | H40: yes
...

Sheet Hospitalisation Details
A1: Customer ID | B1: year | C1: month | D1: date | E1: children | F1: charges | G1: Hospital tier | H1: City tier | I1: State ID
A2: Id2335 | B2: 1992 | C2: Jul | D2: 9 | E2: 0 | F2: 563.84 | G2: tier - 2 | H2: tier - 3 | I2: R1013
A3: Id2334 | B3: 1992 | C3: Nov | D3: 30 | E3: 0 | F3: 570.62 | G3: tier - 2 | H3: tier - 1 | I3: R1013
A4: Id2333 | B4: 1993 | C4: Jun | D4: 30 | E4: 0 | F4: 600 | G4: tier - 2 | H4: tier - 1 | I4: R1013
A5: Id2332 | B5: 1992 | C5: Sep | D5: 13 | E5: 0 | F5: 604.54 | G5: tier - 3 | H5: tier - 3 | I5: R1013
A6: Id2331 | B6: 1998 | C6: Jul | D6: 27 | E6: 0 | F6: 637.26 | G6: tier - 3 | H6: tier - 3 | I6: R1013
A7: Id2330 | B7: 2001 | C7: Nov | D7: 20 | E7: 0 | F7: 646.14 | G7: tier - 3 | H7: tier - 3 | I7: R1012
A8: Id2329 | B8: 1993 | C8: Jun | D8: 1 | E8: 0 | F8: 650 | G8: tier - 3 | H8: tier - 3 | I8: R1013
A9: Id2328 | B9: 1995 | C9: Jul | D9: 4 | E9: 0 | F9: 650 | G9: tier - 3 | H9: tier - 3 | I9: R1013
A10: Id2327 | B10: 2002 | C10: Nov | D10: 29 | E10: 0 | F10: 668 | G10: tier - 3 | H10: tier - 2 | I10: R1012
A11: Id2326 | B11: 1997 | C11: Nov | D11: 9 | E11: 0 | F11: 670 | G11: tier - 3 | H11: tier - 3 | I11: R1013
A12: Id2325 | B12: 2001 | C12: Sep | D12: 12 | E12: 0 | F12: 687.54 | G12: tier - 3 | H12: tier - 2 | I12: R1013
A13: Id2324 | B13: 1999 | C13: Dec | D13: 26 | E13: 0 | F13: 700 | G13: ? | H13: tier - 3 | I13: R1013
... A1050: Id1290 | B1050: 1977 | C1050: Jul | D1050: 26 | E1050: 2 | F1050: 8527.53 | G1050: tier - 2 | H1050: tier - 2 | I1050: R1013
A1051: Id1289 | B1051: ? | C1051: Jul | D1051: 24 | E1051: 0 | F1051: 8534.67 | G1051: tier - 2 | H1051: tier - 3 | I1051: R1024
A1052: Id1288 | B1052: 1981 | C1052: Dec | D1052: 27 | E1052: 3 | F1052: 8538.29 | G1052: tier - 2 | H1052: tier - 3 | I1052: R1024
A1053: Id1287 | B1053: 1975 | C1053: Nov | D1053: 6 | E1053: 1 | F1053: 8539.67 | G1053: tier - 2 | H1053: tier - 3 | I1053: R1011
A1054: Id1286 | B1054: ? | C1054: Dec | D1054: 12 | E1054: 1 | F1054: 8547.69 | G1054: tier - 2 | H1054: tier - 1 | I1054: R1013
A1055: Id1285 | B1055: 1975 | C1055: Aug | D1055: 6 | E1055: 1 | F1055: 8551.35 | G1055: tier - 2 | H1055: tier - 2 | I1055: R1011
A1056: Id1284 | B1056: 1975 | C1056: Aug | D1056: 21 | E1056: 1 | F1056: 8556.91 | G1056: tier - 2 | H1056: tier - 1 | I1056: R1011
A1057: Id1283 | B1057: 1988 | C1057: Sep | D1057: 21 | E1057: 3 | F1057: 8567.25 | G1057: tier - 2 | H1057: tier - 1 | I1057: R1012
A1058: Id1282 | B1058: 1975 | C1058: Sep | D1058: 26 | E1058: 1 | F1058: 8569.86 | G1058: tier - 2 | H1058: tier - 3 | I1058: R1013
A1059: Id1281 | B1059: 1982 | C1059: Dec | D1059: 6 | E1059: 3 | F1059: 8572.04 | G1059: tier - 2 | H1059: tier - 2 | I1059: R1021
A1060: Id1280 | B1060: 1987 | C1060: Nov | D1060: 11 | E1060: 3 | F1060: 8573.3 | G1060: tier - 2 | H1060: tier - 2 | I1060: R1021
A1061: Id1279 | B1061: 1983 | C1061: Dec | D1061: 30 | E1061: 5 | F1061: 8582.3 | G1061: tier - 2 | H1061: tier - 1 | I1061: R1013
A1062: Id1278 | B1062: 1983 | C1062: Jul | D1062: 25 | E1062: 5 | F1062: 8596.83 | G1062: tier - 2 | H1062: tier - 3 | I1062: R1013
A1063: Id1277 | B1063: 1973 | C1063: Jul | D1063: 11 | E1063: 0 | F1063: 8601.33 | G1063: tier - 2 | H1063: tier - 1 | I1063: R1013
A1064: Id1276 | B1064: 1977 | C1064: Sep | D1064: 24 | E1064: 2 | F1064: 8603.82 | G1064: tier - 2 | H1064: tier - 1 | I1064: R1019
A1065: Id1275 | B1065: 1977 | C1065: Nov | D1065: 12 | E1065: 2 | F1065: 8604.48 | G1065: tier - 3 | H1065: tier - 2 | I1065: R1016
A1066: Id1274 | B1066: 1977 | C1066: Oct | D1066: 15 | E1066: 3 | F1066: 8605.36 | G1066: tier - 2 | H1066: tier - 2 | I1066: R1013
... A2344: Id1 | B2344: 1968 | C2344: Oct | D2344: 12 | E2344: 0 | F2344: 63770.43 | G2344: tier - 1 | H2344: tier - 3 | I2344: R1013

Sheet CUSTOMER_NAMES ANSWER
A1: Customer ID | B1: Title | C1: First Name | D1: Last Name
A2: Id1 | B2: Ms | C2: Kelly | D2: Hawks
A3: Id2 | B3: Mr | C3: Matthew D | D3: Lehner
A4: Id3 | B4: Mr | C4: Phil | D4: Lu
A5: Id4 | B5: Ms | C5: Kelsey | D5: Osborne
A6: Id5 | B6: Ms | C6: Kristyn | D6: Kadala
A7: Id6 | B7: Mr | C7: Russell B | D7: Baker
A8: Id7 | B8: Mr | C8: Scott | D8: Macpherson
A9: Id8 | B9: Mr | C9: Stephen | D9: Hallman
A10: Id9 | B10: Mr | C10: Patrick R | D10: Moran
A11: Id10 | B11: Ms | C11: Brooke N | D11: Benner
A12: Id11 | B12: Ms | C12: Paola Andrea | D12: Fierro Vargas
... A2336: Id2335 | B2336: Mr | C2336: Aaron K | D2336: German

Sheet HOSPITAL DETAILS ANSWERS
A1: Customer ID | B1: Year | C1: Month | D1: Date | E1: Date of Birth | F1: Age | G1: Children | H1: Charges | I1: Hospital Tier | J1: City Tier | K1: State ID
A2: Id1 | B2: 1968 | C2: Oct | D2: 12 | E2: =_xlfn.CONCAT(HOSPITILISATION_DETAILS6[[#This Row],[Date]],"-",HOSPITILISATION_DETAILS6[[#This Row],[Month]],"-",HOSPITILISATION_DETAILS6[[#This Row],[Year]]) -> 12-Oct-1968 | F2: =DATEDIF(HOSPITILISATION_DETAILS6[[#This Row],[Date of Birth]],"08-06-2023","Y") -> 54 | G2: 0 | H2: 63771 | I2: Tier - 1 | J2: Tier - 3 | K2: R1013
A3: Id10 | B3: 1978 | C3: Dec | D3: 29 | E3: =_xlfn.CONCAT(HOSPITILISATION_DETAILS6[[#This Row],[Date]],"-",HOSPITILISATION_DETAILS6[[#This Row],[Month]],"-",HOSPITILISATION_DETAILS6[[#This Row],[Year]]) -> 29-Dec-1978 | F3: =DATEDIF(HOSPITILISATION_DETAILS6[[#This Row],[Date of Birth]],"08-06-2023","Y") -> 44 | G3: 0 | H3: 48886 | I3: Tier - 1 | J3: Tier - 2 | K3: R1013
A4: Id100 | B4: 1977 | C4: Jun | D4: 27 | E4: =_xlfn.CONCAT(HOSPITILISATION_DETAILS6[[#This Row],[Date]],"-",HOSPITILISATION_DETAILS6[[#This Row],[Month]],"-",HOSPITILISATION_DETAILS6[[#This Row],[Year]]) -> 27-Jun-1977 | F4: =DATEDIF(HOSPITILISATION_DETAILS6[[#This Row],[Date of Birth]],"08-06-2023","Y") -> 45 | G4: 2 | H4: 40285 | I4: Tier - 1 | J4: Tier - 3 | K4: R1012
A5: Id1000 | B5: 1989 | C5: Dec | D5: 17 | E5: =_xlfn.CONCAT(HOSPITILISATION_DETAILS6[[#This Row],[Date]],"-",HOSPITILISATION_DETAILS6[[#This Row],[Month]],"-",HOSPITILISATION_DETAILS6[[#This Row],[Year]]) -> 17-Dec-1989 | F5: =DATEDIF(HOSPITILISATION_DETAILS6[[#This Row],[Date of Birth]],"08-06-2023","Y") -> 33 | G5: 3 | H5: 11251 | I5: Tier - 3 | J5: Tier - 2 | K5: R1026
A6: Id1001 | B6: 1969 | C6: Dec | D6: 30 | E6: =_xlfn.CONCAT(HOSPITILISATION_DETAILS6[[#This Row],[Date]],"-",HOSPITILISATION_DETAILS6[[#This Row],[Month]],"-",HOSPITILISATION_DETAILS6[[#This Row],[Year]]) -> 30-Dec-1969 | F6: =DATEDIF(HOSPITILISATION_DETAILS6[[#This Row],[Date of Birth]],"08-06-2023","Y") -> 53 | G6: 2 | H6: 11245 | I6: Tier - 3 | J6: Tier - 1 | K6: R1016
A7: Id1002 | B7: 1976 | C7: Jun | D7: 28 | E7: =_xlfn.CONCAT(HOSPITILISATION_DETAILS6[[#This Row],[Date]],"-",HOSPITILISATION_DETAILS6[[#This Row],[Month]],"-",HOSPITILISATION_DETAILS6[[#This Row],[Year]]) -> 28-Jun-1976 | F7: =DATEDIF(HOSPITILISATION_DETAILS6[[#This Row],[Date of Birth]],"08-06-2023","Y") -> 46 | G7: 2 | H7: 11218 | I7: Tier - 3 | J7: Tier - 2 | K7: R1025
A8: Id1003 | B8: 1970 | C8: Jun | D8: 14 | E8: =_xlfn.CONCAT(HOSPITILISATION_DETAILS6[[#This Row],[Date]],"-",HOSPITILISATION_DETAILS6[[#This Row],[Month]],"-",HOSPITILISATION_DETAILS6[[#This Row],[Year]]) -> 14-Jun-1970 | F8: =DATEDIF(HOSPITILISATION_DETAILS6[[#This Row],[Date of Birth]],"08-06-2023","Y") -> 52 | G8: 2 | H8: 11188 | I8: Tier - 3 | J8: Tier - 2 | K8: R1012
A9: Id1004 | B9: 1972 | C9: Sep | D9: 3 | E9: =_xlfn.CONCAT(HOSPITILISATION_DETAILS6[[#This Row],[Date]],"-",HOSPITILISATION_DETAILS6[[#This Row],[Month]],"-",HOSPITILISATION_DETAILS6[[#This Row],[Year]]) -> 3-Sep-1972 | F9: =DATEDIF(HOSPITILISATION_DETAILS6[[#This Row],[Date of Birth]],"08-06-2023","Y") -> 50 | G9: 0 | H9: 11187 | I9: Tier - 3 | J9: Tier - 2 | K9: R1021
A10: Id1005 | B10: 1966 | C10: Aug | D10: 6 | E10: =_xlfn.CONCAT(HOSPITILISATION_DETAILS6[[#This Row],[Date]],"-",HOSPITILISATION_DETAILS6[[#This Row],[Month]],"-",HOSPITILISATION_DETAILS6[[#This Row],[Year]]) -> 6-Aug-1966 | F10: =DATEDIF(HOSPITILISATION_DETAILS6[[#This Row],[Date of Birth]],"08-06-2023","Y") -> 56 | G10: 0 | H10: 11166 | I10: Tier - 3 | J10: Tier - 1 | K10: R1016
A11: Id1006 | B11: 1969 | C11: Jun | D11: 25 | E11: =_xlfn.CONCAT(HOSPITILISATION_DETAILS6[[#This Row],[Date]],"-",HOSPITILISATION_DETAILS6[[#This Row],[Month]],"-",HOSPITILISATION_DETAILS6[[#This Row],[Year]]) -> 25-Jun-1969 | F11: =DATEDIF(HOSPITILISATION_DETAILS6[[#This Row],[Date of Birth]],"08-06-2023","Y") -> 53 | G11: 2 | H11: 11164 | I11: Tier - 3 | J11: Tier - 2 | K11: R1011
A12: Id1007 | B12: 1969 | C12: Nov | D12: 30 | E12: =_xlfn.CONCAT(HOSPITILISATION_DETAILS6[[#This Row],[Date]],"-",HOSPITILISATION_DETAILS6[[#This Row],[Month]],"-",HOSPITILISATION_DETAILS6[[#This Row],[Year]]) -> 30-Nov-1969 | F12: =DATEDIF(HOSPITILISATION_DETAILS6[[#This Row],[Date of Birth]],"08-06-2023","Y") -> 53 | G12: 2 | H12: 11151 | I12: Tier - 3 | J12: Tier - 2 | K12: R1011
A13: Id1008 | B13: 1980 | C13: Aug | D13: 20 | E13: =_xlfn.CONCAT(HOSPITILISATION_DETAILS6[[#This Row],[Date]],"-",HOSPITILISATION_DETAILS6[[#This Row],[Month]],"-",HOSPITILISATION_DETAILS6[[#This Row],[Year]]) -> 20-Aug-1980 | F13: =DATEDIF(HOSPITILISATION_DETAILS6[[#This Row],[Date of Birth]],"08-06-2023","Y") -> 42 | G13: 2 | H13: 11104 | I13: Tier - 3 | J13: Tier - 1 | K13: R1021
... A2337: Unknown | B2337: 2004 | C2337: Nov | D2337: 6 | E2337: =_xlfn.CONCAT(HOSPITILISATION_DETAILS6[[#This Row],[Date]],"-",HOSPITILISATION_DETAILS6[[#This Row],[Month]],"-",HOSPITILISATION_DETAILS6[[#This Row],[Year]]) -> 6-Nov-2004 | F2337: =DATEDIF(HOSPITILISATION_DETAILS6[[#This Row],[Date of Birth]],"08-06-2023","Y") -> 18 | G2337: 0 | H2337: 1138 | I2337: Tier - 3 | J2337: Tier - 1 | K2337: R1013

Sheet MEDICAL EXAMINATION ANSWER
A1: Customer ID | B1: BMI | C1: Weight Status | D1: HBA1C | E1: Diabetese Status | F1: Heart Issues | G1: Any Transplants | H1: Cancer History | I1: Number of Major Surgeries | J1: Smoker
A2: Id1 | B2: 47.41 | C2: {=_xlfn.IFS(Medical_Examinations[[#This Row],[BMI]]<18.5,"Under Weight",Medical_Examinations[[#This Row],[BMI]]<=24.9,"Normal Weight",Medical_Examinations[[#This Row],[BMI]]<=29.9,"Over Weight",Medical_Examinations[[#This Row],[BMI]]>29.9,"Obesity")} -> Obesity | D2: 7.47 | E2: {=_xlfn.IFS(Medical_Examinations[[#This Row],[HBA1C]]<5.7,"Normal",Medical_Examinations[[#This Row],[HBA1C]]<=6.4,"Prediabetes",Medical_Examinations[[#This Row],[HBA1C]]>=6.4,"Diabetes")} -> Diabetes | F2: No | G2: No | H2: No | I2: 0 | J2: Yes
A3: Id10 | B3: 38.06 | C3: {=_xlfn.IFS(Medical_Examinations[[#This Row],[BMI]]<18.5,"Under Weight",Medical_Examinations[[#This Row],[BMI]]<=24.9,"Normal Weight",Medical_Examinations[[#This Row],[BMI]]<=29.9,"Over Weight",Medical_Examinations[[#This Row],[BMI]]>29.9,"Obesity")} -> Obesity | D3: 10.79 | E3: {=_xlfn.IFS(Medical_Examinations[[#This Row],[HBA1C]]<5.7,"Normal",Medical_Examinations[[#This Row],[HBA1C]]<=6.4,"Prediabetes",Medical_Examinations[[#This Row],[HBA1C]]>=6.4,"Diabetes")} -> Diabetes | F3: No | G3: No | H3: No | I3: 0 | J3: Yes
A4: Id100 | B4: 48.2 | C4: {=_xlfn.IFS(Medical_Examinations[[#This Row],[BMI]]<18.5,"Under Weight",Medical_Examinations[[#This Row],[BMI]]<=24.9,"Normal Weight",Medical_Examinations[[#This Row],[BMI]]<=29.9,"Over Weight",Medical_Examinations[[#This Row],[BMI]]>29.9,"Obesity")} -> Obesity | D4: 4.84 | E4: {=_xlfn.IFS(Medical_Examinations[[#This Row],[HBA1C]]<5.7,"Normal",Medical_Examinations[[#This Row],[HBA1C]]<=6.4,"Prediabetes",Medical_Examinations[[#This Row],[HBA1C]]>=6.4,"Diabetes")} -> Normal | F4: No | G4: No | H4: No | I4: 0 | J4: Yes
A5: Id1000 | B5: 39.17 | C5: {=_xlfn.IFS(Medical_Examinations[[#This Row],[BMI]]<18.5,"Under Weight",Medical_Examinations[[#This Row],[BMI]]<=24.9,"Normal Weight",Medical_Examinations[[#This Row],[BMI]]<=29.9,"Over Weight",Medical_Examinations[[#This Row],[BMI]]>29.9,"Obesity")} -> Obesity | D5: 4.15 | E5: {=_xlfn.IFS(Medical_Examinations[[#This Row],[HBA1C]]<5.7,"Normal",Medical_Examinations[[#This Row],[HBA1C]]<=6.4,"Prediabetes",Medical_Examinations[[#This Row],[HBA1C]]>=6.4,"Diabetes")} -> Normal | F5: No | G5: No | H5: No | I5: 0 | J5: No
A6: Id1001 | B6: 26.41 | C6: {=_xlfn.IFS(Medical_Examinations[[#This Row],[BMI]]<18.5,"Under Weight",Medical_Examinations[[#This Row],[BMI]]<=24.9,"Normal Weight",Medical_Examinations[[#This Row],[BMI]]<=29.9,"Over Weight",Medical_Examinations[[#This Row],[BMI]]>29.9,"Obesity")} -> Over Weight | D6: 5.99 | E6: {=_xlfn.IFS(Medical_Examinations[[#This Row],[HBA1C]]<5.7,"Normal",Medical_Examinations[[#This Row],[HBA1C]]<=6.4,"Prediabetes",Medical_Examinations[[#This Row],[HBA1C]]>=6.4,"Diabetes")} -> Prediabetes | F6: Yes | G6: No | H6: Yes | I6: 1 | J6: No
A7: Id1002 | B7: 30.63 | C7: {=_xlfn.IFS(Medical_Examinations[[#This Row],[BMI]]<18.5,"Under Weight",Medical_Examinations[[#This Row],[BMI]]<=24.9,"Normal Weight",Medical_Examinations[[#This Row],[BMI]]<=29.9,"Over Weight",Medical_Examinations[[#This Row],[BMI]]>29.9,"Obesity")} -> Obesity | D7: 5.8 | E7: {=_xlfn.IFS(Medical_Examinations[[#This Row],[HBA1C]]<5.7,"Normal",Medical_Examinations[[#This Row],[HBA1C]]<=6.4,"Prediabetes",Medical_Examinations[[#This Row],[HBA1C]]>=6.4,"Diabetes")} -> Prediabetes | F7: Yes | G7: No | H7: No | I7: 0 | J7: No
A8: Id1003 | B8: 31.73 | C8: {=_xlfn.IFS(Medical_Examinations[[#This Row],[BMI]]<18.5,"Under Weight",Medical_Examinations[[#This Row],[BMI]]<=24.9,"Normal Weight",Medical_Examinations[[#This Row],[BMI]]<=29.9,"Over Weight",Medical_Examinations[[#This Row],[BMI]]>29.9,"Obesity")} -> Obesity | D8: 7.32 | E8: {=_xlfn.IFS(Medical_Examinations[[#This Row],[HBA1C]]<5.7,"Normal",Medical_Examinations[[#This Row],[HBA1C]]<=6.4,"Prediabetes",Medical_Examinations[[#This Row],[HBA1C]]>=6.4,"Diabetes")} -> Diabetes | F8: Yes | G8: No | H8: No | I8: 2 | J8: No
A9: Id1004 | B9: 30.7 | C9: {=_xlfn.IFS(Medical_Examinations[[#This Row],[BMI]]<18.5,"Under Weight",Medical_Examinations[[#This Row],[BMI]]<=24.9,"Normal Weight",Medical_Examinations[[#This Row],[BMI]]<=29.9,"Over Weight",Medical_Examinations[[#This Row],[BMI]]>29.9,"Obesity")} -> Obesity | D9: 5.16 | E9: {=_xlfn.IFS(Medical_Examinations[[#This Row],[HBA1C]]<5.7,"Normal",Medical_Examinations[[#This Row],[HBA1C]]<=6.4,"Prediabetes",Medical_Examinations[[#This Row],[HBA1C]]>=6.4,"Diabetes")} -> Normal | F9: No | G9: No | H9: No | I9: 2 | J9: No
A10: Id1005 | B10: 25.93 | C10: {=_xlfn.IFS(Medical_Examinations[[#This Row],[BMI]]<18.5,"Under Weight",Medical_Examinations[[#This Row],[BMI]]<=24.9,"Normal Weight",Medical_Examinations[[#This Row],[BMI]]<=29.9,"Over Weight",Medical_Examinations[[#This Row],[BMI]]>29.9,"Obesity")} -> Over Weight | D10: 5.96 | E10: {=_xlfn.IFS(Medical_Examinations[[#This Row],[HBA1C]]<5.7,"Normal",Medical_Examinations[[#This Row],[HBA1C]]<=6.4,"Prediabetes",Medical_Examinations[[#This Row],[HBA1C]]>=6.4,"Diabetes")} -> Prediabetes | F10: Yes | G10: No | H10: No | I10: 2 | J10: No
A11: Id1006 | B11: 35.9 | C11: {=_xlfn.IFS(Medical_Examinations[[#This Row],[BMI]]<18.5,"Under Weight",Medical_Examinations[[#This Row],[BMI]]<=24.9,"Normal Weight",Medical_Examinations[[#This Row],[BMI]]<=29.9,"Over Weight",Medical_Examinations[[#This Row],[BMI]]>29.9,"Obesity")} -> Obesity | D11: 4.85 | E11: {=_xlfn.IFS(Medical_Examinations[[#This Row],[HBA1C]]<5.7,"Normal",Medical_Examinations[[#This Row],[HBA1C]]<=6.4,"Prediabetes",Medical_Examinations[[#This Row],[HBA1C]]>=6.4,"Diabetes")} -> Normal | F11: Yes | G11: No | H11: Yes | I11: 1 | J11: No
A12: Id1007 | B12: 26.7 | C12: {=_xlfn.IFS(Medical_Examinations[[#This Row],[BMI]]<18.5,"Under Weight",Medical_Examinations[[#This Row],[BMI]]<=24.9,"Normal Weight",Medical_Examinations[[#This Row],[BMI]]<=29.9,"Over Weight",Medical_Examinations[[#This Row],[BMI]]>29.9,"Obesity")} -> Over Weight | D12: 5.09 | E12: {=_xlfn.IFS(Medical_Examinations[[#This Row],[HBA1C]]<5.7,"Normal",Medical_Examinations[[#This Row],[HBA1C]]<=6.4,"Prediabetes",Medical_Examinations[[#This Row],[HBA1C]]>=6.4,"Diabetes")} -> Normal | F12: Yes | G12: No | H12: Yes | I12: 1 | J12: No
A13: Id1008 | B13: 33.71 | C13: {=_xlfn.IFS(Medical_Examinations[[#This Row],[BMI]]<18.5,"Under Weight",Medical_Examinations[[#This Row],[BMI]]<=24.9,"Normal Weight",Medical_Examinations[[#This Row],[BMI]]<=29.9,"Over Weight",Medical_Examinations[[#This Row],[BMI]]>29.9,"Obesity")} -> Obesity | D13: 4.94 | E13: {=_xlfn.IFS(Medical_Examinations[[#This Row],[HBA1C]]<5.7,"Normal",Medical_Examinations[[#This Row],[HBA1C]]<=6.4,"Prediabetes",Medical_Examinations[[#This Row],[HBA1C]]>=6.4,"Diabetes")} -> Normal | F13: No | G13: No | H13: No | I13: 0 | J13: No
... A2336: Id999 | B2336: 28.6 | C2336: {=_xlfn.IFS(Medical_Examinations[[#This Row],[BMI]]<18.5,"Under Weight",Medical_Examinations[[#This Row],[BMI]]<=24.9,"Normal Weight",Medical_Examinations[[#This Row],[BMI]]<=29.9,"Over Weight",Medical_Examinations[[#This Row],[BMI]]>29.9,"Obesity")} -> Over Weight | D2336: 5.56 | E2336: {=_xlfn.IFS(Medical_Examinations[[#This Row],[HBA1C]]<5.7,"Normal",Medical_Examinations[[#This Row],[HBA1C]]<=6.4,"Prediabetes",Medical_Examinations[[#This Row],[HBA1C]]>=6.4,"Diabetes")} -> Normal | F2336: Yes | G2336: No | H2336: Yes | I2336: 1 | J2336: No

Sheet HEALTH CARE
A1: Customer ID | B1: First Name | C1: BMI | D1: HBA1C | E1: Heart Issues | F1: Any Transplants | G1: Cancer History | H1: Number of Major Surgeries | I1: Smoker | J1: Weight Status | K1: Diabetese Status | L1: Date of Birth | M1: Charges | N1: Hospital Tier | O1: City Tier | P1: State ID | Q1: Age
A2: Id1 | B2: =VLOOKUP(HEALTH_CARE[[#This Row],[Customer ID]],'CUSTOMER_NAMES ANSWER'!A:D,3,FALSE) -> Kelly | C2: =VLOOKUP(HEALTH_CARE[[#This Row],[Customer ID]],'MEDICAL EXAMINATION ANSWER'!A:J,2,FALSE) -> 47.41 | D2: =VLOOKUP(HEALTH_CARE[[#This Row],[Customer ID]],'MEDICAL EXAMINATION ANSWER'!A:J,4,FALSE) -> 7.47 | E2: =VLOOKUP(HEALTH_CARE[[#This Row],[Customer ID]],'MEDICAL EXAMINATION ANSWER'!A:J,6,FALSE) -> No | F2: =VLOOKUP(HEALTH_CARE[[#This Row],[Customer ID]],'MEDICAL EXAMINATION ANSWER'!A:J,7,FALSE) -> No | G2: =VLOOKUP(HEALTH_CARE[[#This Row],[Customer ID]],'MEDICAL EXAMINATION ANSWER'!A:J,8,FALSE) -> No | H2: =VLOOKUP(HEALTH_CARE[[#This Row],[Customer ID]],'MEDICAL EXAMINATION ANSWER'!A:J,9,FALSE) -> 0 | I2: =VLOOKUP(HEALTH_CARE[[#This Row],[Customer ID]],'MEDICAL EXAMINATION ANSWER'!A:J,10,FALSE) -> Yes | J2: =VLOOKUP(HEALTH_CARE[[#This Row],[Customer ID]],'MEDICAL EXAMINATION ANSWER'!A:J,3,FALSE) -> Obesity | K2: =VLOOKUP(HEALTH_CARE[[#This Row],[Customer ID]],'MEDICAL EXAMINATION ANSWER'!A:J,5,FALSE) -> Diabetes | L2: =VLOOKUP(HEALTH_CARE[[#This Row],[Customer ID]],'HOSPITAL DETAILS ANSWERS'!A:K,5,TRUE) -> 12-Oct-1968 | M2: =VLOOKUP(HEALTH_CARE[[#This Row],[Customer ID]],'HOSPITAL DETAILS ANSWERS'!A:K,8,TRUE) -> 63771 | N2: =VLOOKUP(HEALTH_CARE[[#This Row],[Customer ID]],'HOSPITAL DETAILS ANSWERS'!A:K,9,TRUE) -> Tier - 1 | O2: =VLOOKUP(HEALTH_CARE[[#This Row],[Customer ID]],'HOSPITAL DETAILS ANSWERS'!A:K,10,TRUE) -> Tier - 3 | P2: =VLOOKUP(HEALTH_CARE[[#This Row],[Customer ID]],'HOSPITAL DETAILS ANSWERS'!A:K,11,TRUE) -> R1013 | Q2: =VLOOKUP(HEALTH_CARE[[#This Row],[Customer ID]],'HOSPITAL DETAILS ANSWERS'!A:K,6,TRUE) -> 54
A3: Id2 | B3: =VLOOKUP(HEALTH_CARE[[#This Row],[Customer ID]],'CUSTOMER_NAMES ANSWER'!A:D,3,FALSE) -> Matthew D | C3: =VLOOKUP(HEALTH_CARE[[#This Row],[Customer ID]],'MEDICAL EXAMINATION ANSWER'!A:J,2,FALSE) -> 30.36 | D3: =VLOOKUP(HEALTH_CARE[[#This Row],[Customer ID]],'MEDICAL EXAMINATION ANSWER'!A:J,4,FALSE) -> 5.77 | E3: =VLOOKUP(HEALTH_CARE[[#This Row],[Customer ID]],'MEDICAL EXAMINATION ANSWER'!A:J,6,FALSE) -> No | F3: =VLOOKUP(HEALTH_CARE[[#This Row],[Customer ID]],'MEDICAL EXAMINATION ANSWER'!A:J,7,FALSE) -> No | G3: =VLOOKUP(HEALTH_CARE[[#This Row],[Customer ID]],'MEDICAL EXAMINATION ANSWER'!A:J,8,FALSE) -> No | H3: =VLOOKUP(HEALTH_CARE[[#This Row],[Customer ID]],'MEDICAL EXAMINATION ANSWER'!A:J,9,FALSE) -> 0 | I3: =VLOOKUP(HEALTH_CARE[[#This Row],[Customer ID]],'MEDICAL EXAMINATION ANSWER'!A:J,10,FALSE) -> Yes | J3: =VLOOKUP(HEALTH_CARE[[#This Row],[Customer ID]],'MEDICAL EXAMINATION ANSWER'!A:J,3,FALSE) -> Obesity | K3: =VLOOKUP(HEALTH_CARE[[#This Row],[Customer ID]],'MEDICAL EXAMINATION ANSWER'!A:J,5,FALSE) -> Prediabetes | L3: =VLOOKUP(HEALTH_CARE[[#This Row],[Customer ID]],'HOSPITAL DETAILS ANSWERS'!A:K,5,TRUE) -> 8-Jun-1977 | M3: =VLOOKUP(HEALTH_CARE[[#This Row],[Customer ID]],'HOSPITAL DETAILS ANSWERS'!A:K,8,TRUE) -> 62593 | N3: =VLOOKUP(HEALTH_CARE[[#This Row],[Customer ID]],'HOSPITAL DETAILS ANSWERS'!A:K,9,TRUE) -> Tier - 2 | O3: =VLOOKUP(HEALTH_CARE[[#This Row],[Customer ID]],'HOSPITAL DETAILS ANSWERS'!A:K,10,TRUE) -> Tier - 3 | P3: =VLOOKUP(HEALTH_CARE[[#This Row],[Customer ID]],'HOSPITAL DETAILS ANSWERS'!A:K,11,TRUE) -> R1013 | Q3: =VLOOKUP(HEALTH_CARE[[#This Row],[Customer ID]],'HOSPITAL DETAILS ANSWERS'!A:K,6,TRUE) -> 46
A4: Id3 | B4: =VLOOKUP(HEALTH_CARE[[#This Row],[Customer ID]],'CUSTOMER_NAMES ANSWER'!A:D,3,FALSE) -> Phil | C4: =VLOOKUP(HEALTH_CARE[[#This Row],[Customer ID]],'MEDICAL EXAMINATION ANSWER'!A:J,2,FALSE) -> 34.48 | D4: =VLOOKUP(HEALTH_CARE[[#This Row],[Customer ID]],'MEDICAL EXAMINATION ANSWER'!A:J,4,FALSE) -> 11.87 | E4: =VLOOKUP(HEALTH_CARE[[#This Row],[Customer ID]],'MEDICAL EXAMINATION ANSWER'!A:J,6,FALSE) -> Yes | F4: =VLOOKUP(HEALTH_CARE[[#This Row],[Customer ID]],'MEDICAL EXAMINATION ANSWER'!A:J,7,FALSE) -> No | G4: =VLOOKUP(HEALTH_CARE[[#This Row],[Customer ID]],'MEDICAL EXAMINATION ANSWER'!A:J,8,FALSE) -> No | H4: =VLOOKUP(HEALTH_CARE[[#This Row],[Customer ID]],'MEDICAL EXAMINATION ANSWER'!A:J,9,FALSE) -> 2 | I4: =VLOOKUP(HEALTH_CARE[[#This Row],[Customer ID]],'MEDICAL EXAMINATION ANSWER'!A:J,10,FALSE) -> Yes | J4: =VLOOKUP(HEALTH_CARE[[#This Row],[Customer ID]],'MEDICAL EXAMINATION ANSWER'!A:J,3,FALSE) -> Obesity | K4: =VLOOKUP(HEALTH_CARE[[#This Row],[Customer ID]],'MEDICAL EXAMINATION ANSWER'!A:J,5,FALSE) -> Diabetes | L4: =VLOOKUP(HEALTH_CARE[[#This Row],[Customer ID]],'HOSPITAL DETAILS ANSWERS'!A:K,5,TRUE) -> 11-Sep-1970 | M4: =VLOOKUP(HEALTH_CARE[[#This Row],[Customer ID]],'HOSPITAL DETAILS ANSWERS'!A:K,8,TRUE) -> 60022 | N4: =VLOOKUP(HEALTH_CARE[[#This Row],[Customer ID]],'HOSPITAL DETAILS ANSWERS'!A:K,9,TRUE) -> Tier - 1 | O4: =VLOOKUP(HEALTH_CARE[[#This Row],[Customer ID]],'HOSPITAL DETAILS ANSWERS'!A:K,10,TRUE) -> Tier - 1 | P4: =VLOOKUP(HEALTH_CARE[[#This Row],[Customer ID]],'HOSPITAL DETAILS ANSWERS'!A:K,11,TRUE) -> R1012 | Q4: =VLOOKUP(HEALTH_CARE[[#This Row],[Customer ID]],'HOSPITAL DETAILS ANSWERS'!A:K,6,TRUE) -> 52
A5: Id4 | B5: =VLOOKUP(HEALTH_CARE[[#This Row],[Customer ID]],'CUSTOMER_NAMES ANSWER'!A:D,3,FALSE) -> Kelsey | C5: =VLOOKUP(HEALTH_CARE[[#This Row],[Customer ID]],'MEDICAL EXAMINATION ANSWER'!A:J,2,FALSE) -> 38.09 | D5: =VLOOKUP(HEALTH_CARE[[#This Row],[Customer ID]],'MEDICAL EXAMINATION ANSWER'!A:J,4,FALSE) -> 6.05 | E5: =VLOOKUP(HEALTH_CARE[[#This Row],[Customer ID]],'MEDICAL EXAMINATION ANSWER'!A:J,6,FALSE) -> No | F5: =VLOOKUP(HEALTH_CARE[[#This Row],[Customer ID]],'MEDICAL EXAMINATION ANSWER'!A:J,7,FALSE) -> No | G5: =VLOOKUP(HEALTH_CARE[[#This Row],[Customer ID]],'MEDICAL EXAMINATION ANSWER'!A:J,8,FALSE) -> No | H5: =VLOOKUP(HEALTH_CARE[[#This Row],[Customer ID]],'MEDICAL EXAMINATION ANSWER'!A:J,9,FALSE) -> 0 | I5: =VLOOKUP(HEALTH_CARE[[#This Row],[Customer ID]],'MEDICAL EXAMINATION ANSWER'!A:J,10,FALSE) -> Yes | J5: =VLOOKUP(HEALTH_CARE[[#This Row],[Customer ID]],'MEDICAL EXAMINATION ANSWER'!A:J,3,FALSE) -> Obesity | K5: =VLOOKUP(HEALTH_CARE[[#This Row],[Customer ID]],'MEDICAL EXAMINATION ANSWER'!A:J,5,FALSE) -> Prediabetes | L5: =VLOOKUP(HEALTH_CARE[[#This Row],[Customer ID]],'HOSPITAL DETAILS ANSWERS'!A:K,5,TRUE) -> 6-Jun-1991 | M5: =VLOOKUP(HEALTH_CARE[[#This Row],[Customer ID]],'HOSPITAL DETAILS ANSWERS'!A:K,8,TRUE) -> 58572 | N5: =VLOOKUP(HEALTH_CARE[[#This Row],[Customer ID]],'HOSPITAL DETAILS ANSWERS'!A:K,9,TRUE) -> Tier - 1 | O5: =VLOOKUP(HEALTH_CARE[[#This Row],[Customer ID]],'HOSPITAL DETAILS ANSWERS'!A:K,10,TRUE) -> Tier - 3 | P5: =VLOOKUP(HEALTH_CARE[[#This Row],[Customer ID]],'HOSPITAL DETAILS ANSWERS'!A:K,11,TRUE) -> R1024 | Q5: =VLOOKUP(HEALTH_CARE[[#This Row],[Customer ID]],'HOSPITAL DETAILS ANSWERS'!A:K,6,TRUE) -> 32
A6: Id5 | B6: =VLOOKUP(HEALTH_CARE[[#This Row],[Customer ID]],'CUSTOMER_NAMES ANSWER'!A:D,3,FALSE) -> Kristyn | C6: =VLOOKUP(HEALTH_CARE[[#This Row],[Customer ID]],'MEDICAL EXAMINATION ANSWER'!A:J,2,FALSE) -> 35.53 | D6: =VLOOKUP(HEALTH_CARE[[#This Row],[Customer ID]],'MEDICAL EXAMINATION ANSWER'!A:J,4,FALSE) -> 5.45 | E6: =VLOOKUP(HEALTH_CARE[[#This Row],[Customer ID]],'MEDICAL EXAMINATION ANSWER'!A:J,6,FALSE) -> No | F6: =VLOOKUP(HEALTH_CARE[[#This Row],[Customer ID]],'MEDICAL EXAMINATION ANSWER'!A:J,7,FALSE) -> No | G6: =VLOOKUP(HEALTH_CARE[[#This Row],[Customer ID]],'MEDICAL EXAMINATION ANSWER'!A:J,8,FALSE) -> No | H6: =VLOOKUP(HEALTH_CARE[[#This Row],[Customer ID]],'MEDICAL EXAMINATION ANSWER'!A:J,9,FALSE) -> 0 | I6: =VLOOKUP(HEALTH_CARE[[#This Row],[Customer ID]],'MEDICAL EXAMINATION ANSWER'!A:J,10,FALSE) -> Yes | J6: =VLOOKUP(HEALTH_CARE[[#This Row],[Customer ID]],'MEDICAL EXAMINATION ANSWER'!A:J,3,FALSE) -> Obesity | K6: =VLOOKUP(HEALTH_CARE[[#This Row],[Customer ID]],'MEDICAL EXAMINATION ANSWER'!A:J,5,FALSE) -> Normal | L6: =VLOOKUP(HEALTH_CARE[[#This Row],[Customer ID]],'HOSPITAL DETAILS ANSWERS'!A:K,5,TRUE) -> 19-Jun-1989 | M6: =VLOOKUP(HEALTH_CARE[[#This Row],[Customer ID]],'HOSPITAL DETAILS ANSWERS'!A:K,8,TRUE) -> 55136 | N6: =VLOOKUP(HEALTH_CARE[[#This Row],[Customer ID]],'HOSPITAL DETAILS ANSWERS'!A:K,9,TRUE) -> Tier - 1 | O6: =VLOOKUP(HEALTH_CARE[[#This Row],[Customer ID]],'HOSPITAL DETAILS ANSWERS'!A:K,10,TRUE) -> Tier - 2 | P6: =VLOOKUP(HEALTH_CARE[[#This Row],[Customer ID]],'HOSPITAL DETAILS ANSWERS'!A:K,11,TRUE) -> R1012 | Q6: =VLOOKUP(HEALTH_CARE[[#This Row],[Customer ID]],'HOSPITAL DETAILS ANSWERS'!A:K,6,TRUE) -> 33
A7: Id6 | B7: =VLOOKUP(HEALTH_CARE[[#This Row],[Customer ID]],'CUSTOMER_NAMES ANSWER'!A:D,3,FALSE) -> Russell B | C7: =VLOOKUP(HEALTH_CARE[[#This Row],[Customer ID]],'MEDICAL EXAMINATION ANSWER'!A:J,2,FALSE) -> 32.8 | D7: =VLOOKUP(HEALTH_CARE[[#This Row],[Customer ID]],'MEDICAL EXAMINATION ANSWER'!A:J,4,FALSE) -> 6.59 | E7: =VLOOKUP(HEALTH_CARE[[#This Row],[Customer ID]],'MEDICAL EXAMINATION ANSWER'!A:J,6,FALSE) -> No | F7: =VLOOKUP(HEALTH_CARE[[#This Row],[Customer ID]],'MEDICAL EXAMINATION ANSWER'!A:J,7,FALSE) -> No | G7: =VLOOKUP(HEALTH_CARE[[#This Row],[Customer ID]],'MEDICAL EXAMINATION ANSWER'!A:J,8,FALSE) -> No | H7: =VLOOKUP(HEALTH_CARE[[#This Row],[Customer ID]],'MEDICAL EXAMINATION ANSWER'!A:J,9,FALSE) -> 0 | I7: =VLOOKUP(HEALTH_CARE[[#This Row],[Customer ID]],'MEDICAL EXAMINATION ANSWER'!A:J,10,FALSE) -> Yes | J7: =VLOOKUP(HEALTH_CARE[[#This Row],[Customer ID]],'MEDICAL EXAMINATION ANSWER'!A:J,3,FALSE) -> Obesity | K7: =VLOOKUP(HEALTH_CARE[[#This Row],[Customer ID]],'MEDICAL EXAMINATION ANSWER'!A:J,5,FALSE) -> Diabetes | L7: =VLOOKUP(HEALTH_CARE[[#This Row],[Customer ID]],'HOSPITAL DETAILS ANSWERS'!A:K,5,TRUE) -> 4-Aug-1962 | M7: =VLOOKUP(HEALTH_CARE[[#This Row],[Customer ID]],'HOSPITAL DETAILS ANSWERS'!A:K,8,TRUE) -> 52591 | N7: =VLOOKUP(HEALTH_CARE[[#This Row],[Customer ID]],'HOSPITAL DETAILS ANSWERS'!A:K,9,TRUE) -> Tier - 1 | O7: =VLOOKUP(HEALTH_CARE[[#This Row],[Customer ID]],'HOSPITAL DETAILS ANSWERS'!A:K,10,TRUE) -> Tier - 3 | P7: =VLOOKUP(HEALTH_CARE[[#This Row],[Customer ID]],'HOSPITAL DETAILS ANSWERS'!A:K,11,TRUE) -> R1011 | Q7: =VLOOKUP(HEALTH_CARE[[#This Row],[Customer ID]],'HOSPITAL DETAILS ANSWERS'!A:K,6,TRUE) -> 60
A8: Id7 | B8: =VLOOKUP(HEALTH_CARE[[#This Row],[Customer ID]],'CUSTOMER_NAMES ANSWER'!A:D,3,FALSE) -> Scott | C8: =VLOOKUP(HEALTH_CARE[[#This Row],[Customer ID]],'MEDICAL EXAMINATION ANSWER'!A:J,2,FALSE) -> 36.4 | D8: =VLOOKUP(HEALTH_CARE[[#This Row],[Customer ID]],'MEDICAL EXAMINATION ANSWER'!A:J,4,FALSE) -> 6.07 | E8: =VLOOKUP(HEALTH_CARE[[#This Row],[Customer ID]],'MEDICAL EXAMINATION ANSWER'!A:J,6,FALSE) -> No | F8: =VLOOKUP(HEALTH_CARE[[#This Row],[Customer ID]],'MEDICAL EXAMINATION ANSWER'!A:J,7,FALSE) -> No | G8: =VLOOKUP(HEALTH_CARE[[#This Row],[Customer ID]],'MEDICAL EXAMINATION ANSWER'!A:J,8,FALSE) -> No | H8: =VLOOKUP(HEALTH_CARE[[#This Row],[Customer ID]],'MEDICAL EXAMINATION ANSWER'!A:J,9,FALSE) -> 0 | I8: =VLOOKUP(HEALTH_CARE[[#This Row],[Customer ID]],'MEDICAL EXAMINATION ANSWER'!A:J,10,FALSE) -> Yes | J8: =VLOOKUP(HEALTH_CARE[[#This Row],[Customer ID]],'MEDICAL EXAMINATION ANSWER'!A:J,3,FALSE) -> Obesity | K8: =VLOOKUP(HEALTH_CARE[[#This Row],[Customer ID]],'MEDICAL EXAMINATION ANSWER'!A:J,5,FALSE) -> Prediabetes | L8: =VLOOKUP(HEALTH_CARE[[#This Row],[Customer ID]],'HOSPITAL DETAILS ANSWERS'!A:K,5,TRUE) -> 27-Oct-1994 | M8: =VLOOKUP(HEALTH_CARE[[#This Row],[Customer ID]],'HOSPITAL DETAILS ANSWERS'!A:K,8,TRUE) -> 51195 | N8: =VLOOKUP(HEALTH_CARE[[#This Row],[Customer ID]],'HOSPITAL DETAILS ANSWERS'!A:K,9,TRUE) -> Tier - 1 | O8: =VLOOKUP(HEALTH_CARE[[#This Row],[Customer ID]],'HOSPITAL DETAILS ANSWERS'!A:K,10,TRUE) -> Tier - 3 | P8: =VLOOKUP(HEALTH_CARE[[#This Row],[Customer ID]],'HOSPITAL DETAILS ANSWERS'!A:K,11,TRUE) -> R1011 | Q8: =VLOOKUP(HEALTH_CARE[[#This Row],[Customer ID]],'HOSPITAL DETAILS ANSWERS'!A:K,6,TRUE) -> 28
A9: Id8 | B9: =VLOOKUP(HEALTH_CARE[[#This Row],[Customer ID]],'CUSTOMER_NAMES ANSWER'!A:D,3,FALSE) -> Stephen | C9: =VLOOKUP(HEALTH_CARE[[#This Row],[Customer ID]],'MEDICAL EXAMINATION ANSWER'!A:J,2,FALSE) -> 36.96 | D9: =VLOOKUP(HEALTH_CARE[[#This Row],[Customer ID]],'MEDICAL EXAMINATION ANSWER'!A:J,4,FALSE) -> 7.93 | E9: =VLOOKUP(HEALTH_CARE[[#This Row],[Customer ID]],'MEDICAL EXAMINATION ANSWER'!A:J,6,FALSE) -> No | F9: =VLOOKUP(HEALTH_CARE[[#This Row],[Customer ID]],'MEDICAL EXAMINATION ANSWER'!A:J,7,FALSE) -> No | G9: =VLOOKUP(HEALTH_CARE[[#This Row],[Customer ID]],'MEDICAL EXAMINATION ANSWER'!A:J,8,FALSE) -> No | H9: =VLOOKUP(HEALTH_CARE[[#This Row],[Customer ID]],'MEDICAL EXAMINATION ANSWER'!A:J,9,FALSE) -> 3 | I9: =VLOOKUP(HEALTH_CARE[[#This Row],[Customer ID]],'MEDICAL EXAMINATION ANSWER'!A:J,10,FALSE) -> Yes | J9: =VLOOKUP(HEALTH_CARE[[#This Row],[Customer ID]],'MEDICAL EXAMINATION ANSWER'!A:J,3,FALSE) -> Obesity | K9: =VLOOKUP(HEALTH_CARE[[#This Row],[Customer ID]],'MEDICAL EXAMINATION ANSWER'!A:J,5,FALSE) -> Diabetes | L9: =VLOOKUP(HEALTH_CARE[[#This Row],[Customer ID]],'HOSPITAL DETAILS ANSWERS'!A:K,5,TRUE) -> 27-Jun-1958 | M9: =VLOOKUP(HEALTH_CARE[[#This Row],[Customer ID]],'HOSPITAL DETAILS ANSWERS'!A:K,8,TRUE) -> 49578 | N9: =VLOOKUP(HEALTH_CARE[[#This Row],[Customer ID]],'HOSPITAL DETAILS ANSWERS'!A:K,9,TRUE) -> Tier - 2 | O9: =VLOOKUP(HEALTH_CARE[[#This Row],[Customer ID]],'HOSPITAL DETAILS ANSWERS'!A:K,10,TRUE) -> Tier - 2 | P9: =VLOOKUP(HEALTH_CARE[[#This Row],[Customer ID]],'HOSPITAL DETAILS ANSWERS'!A:K,11,TRUE) -> R1013 | Q9: =VLOOKUP(HEALTH_CARE[[#This Row],[Customer ID]],'HOSPITAL DETAILS ANSWERS'!A:K,6,TRUE) -> 64
A10: Id9 | B10: =VLOOKUP(HEALTH_CARE[[#This Row],[Customer ID]],'CUSTOMER_NAMES ANSWER'!A:D,3,FALSE) -> Patrick R | C10: =VLOOKUP(HEALTH_CARE[[#This Row],[Customer ID]],'MEDICAL EXAMINATION ANSWER'!A:J,2,FALSE) -> 41.14 | D10: =VLOOKUP(HEALTH_CARE[[#This Row],[Customer ID]],'MEDICAL EXAMINATION ANSWER'!A:J,4,FALSE) -> 9.58 | E10: =VLOOKUP(HEALTH_CARE[[#This Row],[Customer ID]],'MEDICAL EXAMINATION ANSWER'!A:J,6,FALSE) -> Yes | F10: =VLOOKUP(HEALTH_CARE[[#This Row],[Customer ID]],'MEDICAL EXAMINATION ANSWER'!A:J,7,FALSE) -> No | G10: =VLOOKUP(HEALTH_CARE[[#This Row],[Customer ID]],'MEDICAL EXAMINATION ANSWER'!A:J,8,FALSE) -> Yes | H10: =VLOOKUP(HEALTH_CARE[[#This Row],[Customer ID]],'MEDICAL EXAMINATION ANSWER'!A:J,9,FALSE) -> 1 | I10: =VLOOKUP(HEALTH_CARE[[#This Row],[Customer ID]],'MEDICAL EXAMINATION ANSWER'!A:J,10,FALSE) -> Yes | J10: =VLOOKUP(HEALTH_CARE[[#This Row],[Customer ID]],'MEDICAL EXAMINATION ANSWER'!A:J,3,FALSE) -> Obesity | K10: =VLOOKUP(HEALTH_CARE[[#This Row],[Customer ID]],'MEDICAL EXAMINATION ANSWER'!A:J,5,FALSE) -> Diabetes | L10: =VLOOKUP(HEALTH_CARE[[#This Row],[Customer ID]],'HOSPITAL DETAILS ANSWERS'!A:K,5,TRUE) -> 4-Sep-1963 | M10: =VLOOKUP(HEALTH_CARE[[#This Row],[Customer ID]],'HOSPITAL DETAILS ANSWERS'!A:K,8,TRUE) -> 48971 | N10: =VLOOKUP(HEALTH_CARE[[#This Row],[Customer ID]],'HOSPITAL DETAILS ANSWERS'!A:K,9,TRUE) -> Tier - 1 | O10: =VLOOKUP(HEALTH_CARE[[#This Row],[Customer ID]],'HOSPITAL DETAILS ANSWERS'!A:K,10,TRUE) -> Tier - 2 | P10: =VLOOKUP(HEALTH_CARE[[#This Row],[Customer ID]],'HOSPITAL DETAILS ANSWERS'!A:K,11,TRUE) -> R1013 | Q10: =VLOOKUP(HEALTH_CARE[[#This Row],[Customer ID]],'HOSPITAL DETAILS ANSWERS'!A:K,6,TRUE) -> 59
A11: Id10 | B11: =VLOOKUP(HEALTH_CARE[[#This Row],[Customer ID]],'CUSTOMER_NAMES ANSWER'!A:D,3,FALSE) -> Brooke N | C11: =VLOOKUP(HEALTH_CARE[[#This Row],[Customer ID]],'MEDICAL EXAMINATION ANSWER'!A:J,2,FALSE) -> 38.06 | D11: =VLOOKUP(HEALTH_CARE[[#This Row],[Customer ID]],'MEDICAL EXAMINATION ANSWER'!A:J,4,FALSE) -> 10.79 | E11: =VLOOKUP(HEALTH_CARE[[#This Row],[Customer ID]],'MEDICAL EXAMINATION ANSWER'!A:J,6,FALSE) -> No | F11: =VLOOKUP(HEALTH_CARE[[#This Row],[Customer ID]],'MEDICAL EXAMINATION ANSWER'!A:J,7,FALSE) -> No | G11: =VLOOKUP(HEALTH_CARE[[#This Row],[Customer ID]],'MEDICAL EXAMINATION ANSWER'!A:J,8,FALSE) -> No | H11: =VLOOKUP(HEALTH_CARE[[#This Row],[Customer ID]],'MEDICAL EXAMINATION ANSWER'!A:J,9,FALSE) -> 0 | I11: =VLOOKUP(HEALTH_CARE[[#This Row],[Customer ID]],'MEDICAL EXAMINATION ANSWER'!A:J,10,FALSE) -> Yes | J11: =VLOOKUP(HEALTH_CARE[[#This Row],[Customer ID]],'MEDICAL EXAMINATION ANSWER'!A:J,3,FALSE) -> Obesity | K11: =VLOOKUP(HEALTH_CARE[[#This Row],[Customer ID]],'MEDICAL EXAMINATION ANSWER'!A:J,5,FALSE) -> Diabetes | L11: =VLOOKUP(HEALTH_CARE[[#This Row],[Customer ID]],'HOSPITAL DETAILS ANSWERS'!A:K,5,TRUE) -> 29-Dec-1978 | M11: =VLOOKUP(HEALTH_CARE[[#This Row],[Customer ID]],'HOSPITAL DETAILS ANSWERS'!A:K,8,TRUE) -> 48886 | N11: =VLOOKUP(HEALTH_CARE[[#This Row],[Customer ID]],'HOSPITAL DETAILS ANSWERS'!A:K,9,TRUE) -> Tier - 1 | O11: =VLOOKUP(HEALTH_CARE[[#This Row],[Customer ID]],'HOSPITAL DETAILS ANSWERS'!A:K,10,TRUE) -> Tier - 2 | P11: =VLOOKUP(HEALTH_CARE[[#This Row],[Customer ID]],'HOSPITAL DETAILS ANSWERS'!A:K,11,TRUE) -> R1013 | Q11: =VLOOKUP(HEALTH_CARE[[#This Row],[Customer ID]],'HOSPITAL DETAILS ANSWERS'!A:K,6,TRUE) -> 44
A12: Id11 | B12: =VLOOKUP(HEALTH_CARE[[#This Row],[Customer ID]],'CUSTOMER_NAMES ANSWER'!A:D,3,FALSE) -> Paola Andrea | C12: =VLOOKUP(HEALTH_CARE[[#This Row],[Customer ID]],'MEDICAL EXAMINATION ANSWER'!A:J,2,FALSE) -> 37.7 | D12: =VLOOKUP(HEALTH_CARE[[#This Row],[Customer ID]],'MEDICAL EXAMINATION ANSWER'!A:J,4,FALSE) -> 5.96 | E12: =VLOOKUP(HEALTH_CARE[[#This Row],[Customer ID]],'MEDICAL EXAMINATION ANSWER'!A:J,6,FALSE) -> Yes | F12: =VLOOKUP(HEALTH_CARE[[#This Row],[Customer ID]],'MEDICAL EXAMINATION ANSWER'!A:J,7,FALSE) -> No | G12: =VLOOKUP(HEALTH_CARE[[#This Row],[Customer ID]],'MEDICAL EXAMINATION ANSWER'!A:J,8,FALSE) -> No | H12: =VLOOKUP(HEALTH_CARE[[#This Row],[Customer ID]],'MEDICAL EXAMINATION ANSWER'!A:J,9,FALSE) -> 2 | I12: =VLOOKUP(HEALTH_CARE[[#This Row],[Customer ID]],'MEDICAL EXAMINATION ANSWER'!A:J,10,FALSE) -> Yes | J12: =VLOOKUP(HEALTH_CARE[[#This Row],[Customer ID]],'MEDICAL EXAMINATION ANSWER'!A:J,3,FALSE) -> Obesity | K12: =VLOOKUP(HEALTH_CARE[[#This Row],[Customer ID]],'MEDICAL EXAMINATION ANSWER'!A:J,5,FALSE) -> Prediabetes | L12: =VLOOKUP(HEALTH_CARE[[#This Row],[Customer ID]],'HOSPITAL DETAILS ANSWERS'!A:K,5,TRUE) -> 22-Jul-1959 | M12: =VLOOKUP(HEALTH_CARE[[#This Row],[Customer ID]],'HOSPITAL DETAILS ANSWERS'!A:K,8,TRUE) -> 48825 | N12: =VLOOKUP(HEALTH_CARE[[#This Row],[Customer ID]],'HOSPITAL DETAILS ANSWERS'!A:K,9,TRUE) -> Tier - 2 | O12: =VLOOKUP(HEALTH_CARE[[#This Row],[Customer ID]],'HOSPITAL DETAILS ANSWERS'!A:K,10,TRUE) -> Tier - 1 | P12: =VLOOKUP(HEALTH_CARE[[#This Row],[Customer ID]],'HOSPITAL DETAILS ANSWERS'!A:K,11,TRUE) -> R1011 | Q12: =VLOOKUP(HEALTH_CARE[[#This Row],[Customer ID]],'HOSPITAL DETAILS ANSWERS'!A:K,6,TRUE) -> 63
A13: Id12 | B13: =VLOOKUP(HEALTH_CARE[[#This Row],[Customer ID]],'CUSTOMER_NAMES ANSWER'!A:D,3,FALSE) -> David | C13: =VLOOKUP(HEALTH_CARE[[#This Row],[Customer ID]],'MEDICAL EXAMINATION ANSWER'!A:J,2,FALSE) -> 42.13 | D13: =VLOOKUP(HEALTH_CARE[[#This Row],[Customer ID]],'MEDICAL EXAMINATION ANSWER'!A:J,4,FALSE) -> 11.9 | E13: =VLOOKUP(HEALTH_CARE[[#This Row],[Customer ID]],'MEDICAL EXAMINATION ANSWER'!A:J,6,FALSE) -> No | F13: =VLOOKUP(HEALTH_CARE[[#This Row],[Customer ID]],'MEDICAL EXAMINATION ANSWER'!A:J,7,FALSE) -> No | G13: =VLOOKUP(HEALTH_CARE[[#This Row],[Customer ID]],'MEDICAL EXAMINATION ANSWER'!A:J,8,FALSE) -> No | H13: =VLOOKUP(HEALTH_CARE[[#This Row],[Customer ID]],'MEDICAL EXAMINATION ANSWER'!A:J,9,FALSE) -> 0 | I13: =VLOOKUP(HEALTH_CARE[[#This Row],[Customer ID]],'MEDICAL EXAMINATION ANSWER'!A:J,10,FALSE) -> Yes | J13: =VLOOKUP(HEALTH_CARE[[#This Row],[Customer ID]],'MEDICAL EXAMINATION ANSWER'!A:J,3,FALSE) -> Obesity | K13: =VLOOKUP(HEALTH_CARE[[#This Row],[Customer ID]],'MEDICAL EXAMINATION ANSWER'!A:J,5,FALSE) -> Diabetes | L13: =VLOOKUP(HEALTH_CARE[[#This Row],[Customer ID]],'HOSPITAL DETAILS ANSWERS'!A:K,5,TRUE) -> 27-Oct-1965 | M13: =VLOOKUP(HEALTH_CARE[[#This Row],[Customer ID]],'HOSPITAL DETAILS ANSWERS'!A:K,8,TRUE) -> 48676 | N13: =VLOOKUP(HEALTH_CARE[[#This Row],[Customer ID]],'HOSPITAL DETAILS ANSWERS'!A:K,9,TRUE) -> Tier - 1 | O13: =VLOOKUP(HEALTH_CARE[[#This Row],[Customer ID]],'HOSPITAL DETAILS ANSWERS'!A:K,10,TRUE) -> Tier - 2 | P13: =VLOOKUP(HEALTH_CARE[[#This Row],[Customer ID]],'HOSPITAL DETAILS ANSWERS'!A:K,11,TRUE) -> R1013 | Q13: =VLOOKUP(HEALTH_CARE[[#This Row],[Customer ID]],'HOSPITAL DETAILS ANSWERS'!A:K,6,TRUE) -> 57
... A2336: Id2335 | B2336: =VLOOKUP(HEALTH_CARE[[#This Row],[Customer ID]],'CUSTOMER_NAMES ANSWER'!A:D,3,FALSE) -> Aaron K | C2336: =VLOOKUP(HEALTH_CARE[[#This Row],[Customer ID]],'MEDICAL EXAMINATION ANSWER'!A:J,2,FALSE) -> 17.58 | D2336: =VLOOKUP(HEALTH_CARE[[#This Row],[Customer ID]],'MEDICAL EXAMINATION ANSWER'!A:J,4,FALSE) -> 4.51 | E2336: =VLOOKUP(HEALTH_CARE[[#This Row],[Customer ID]],'MEDICAL EXAMINATION ANSWER'!A:J,6,FALSE) -> No | F2336: =VLOOKUP(HEALTH_CARE[[#This Row],[Customer ID]],'MEDICAL EXAMINATION ANSWER'!A:J,7,FALSE) -> No | G2336: =VLOOKUP(HEALTH_CARE[[#This Row],[Customer ID]],'MEDICAL EXAMINATION ANSWER'!A:J,8,FALSE) -> No | H2336: =VLOOKUP(HEALTH_CARE[[#This Row],[Customer ID]],'MEDICAL EXAMINATION ANSWER'!A:J,9,FALSE) -> 1 | I2336: =VLOOKUP(HEALTH_CARE[[#This Row],[Customer ID]],'MEDICAL EXAMINATION ANSWER'!A:J,10,FALSE) -> No | J2336: =VLOOKUP(HEALTH_CARE[[#This Row],[Customer ID]],'MEDICAL EXAMINATION ANSWER'!A:J,3,FALSE) -> Under Weight | K2336: =VLOOKUP(HEALTH_CARE[[#This Row],[Customer ID]],'MEDICAL EXAMINATION ANSWER'!A:J,5,FALSE) -> Normal | L2336: =VLOOKUP(HEALTH_CARE[[#This Row],[Customer ID]],'HOSPITAL DETAILS ANSWERS'!A:K,5,TRUE) -> 9-Jul-1992 | M2336: =VLOOKUP(HEALTH_CARE[[#This Row],[Customer ID]],'HOSPITAL DETAILS ANSWERS'!A:K,8,TRUE) -> 564 | N2336: =VLOOKUP(HEALTH_CARE[[#This Row],[Customer ID]],'HOSPITAL DETAILS ANSWERS'!A:K,9,TRUE) -> Tier - 2 | O2336: =VLOOKUP(HEALTH_CARE[[#This Row],[Customer ID]],'HOSPITAL DETAILS ANSWERS'!A:K,10,TRUE) -> Tier - 3 | P2336: =VLOOKUP(HEALTH_CARE[[#This Row],[Customer ID]],'HOSPITAL DETAILS ANSWERS'!A:K,11,TRUE) -> R1013 | Q2336: =VLOOKUP(HEALTH_CARE[[#This Row],[Customer ID]],'HOSPITAL DETAILS ANSWERS'!A:K,6,TRUE) -> 30

Sheet PIVOT TABLE
A3: Count of Customer ID | B3: Column Labels | F3: Average of Charges | G3: Column Labels | L3: Row Labels | M3: Average of BMI | N3: Average of HBA1C
A4: Row Labels | B4: No | C4: Yes | D4: Grand Total | F4: Row Labels | G4: Diabetes | H4: Normal | I4: Prediabetes | J4: Grand Total | L4: 18 | M4: 31.260319 | N4: 5.1409574
A5: No | B5: 0.65952891 | C5: 0.17301927 | D5: 0.83254818 | F5: Normal Weight | G5: 12510.304 | H5: 7897.566 | I5: 10390.42 | J5: 9842.993 | L5: 19 | M5: 29.654535 | N5: 5.1781395
A6: Yes | B6: 0.13147752 | C6: 0.035974304 | D6: 0.16745182 | F6: Obesity | G6: 19103.911 | H6: 15140.917 | I6: 15503.249 | J6: 16612.758 | L6: 20 | M6: 28.017931 | N6: 9.3244828
A7: Grand Total | B7: 0.79100642 | C7: 0.20899358 | D7: 1 | F7: Over Weight | G7: 13887.205 | H7: 10377.135 | I7: 10008.881 | J7: 11410.287 | L7: 21 | M7: 29.273953 | N7: 5.1174419
F8: Under Weight | G8: 7425.3939 | H8: 6911.3171 | I8: 5626.4643 | J8: 6899.6875 | L8: 22 | M8: 32.581731 | N8: 5.2767308
F9: Grand Total | G9: 15974.041 | H9: 12091.205 | I9: 12691.465 | J9: 13530.407 | L9: 23 | M9: 30.8296 | N9: 5.1892
L10: 24 | M10: 29.017826 | N10: 5.1626087
L11: 25 | M11: 30.344035 | N11: 5.2589474
L12: 26 | M12: 30.441818 | N12: 5.1029545
L13: 27 | M13: 30.316667 | N13: 4.9407843
L14: 28 | M14: 31.029464 | N14: 5.2207143
L15: 29 | M15: 30.763208 | N15: 5.2043396
L16: 30 | M16: 33.517857 | N16: 5.1835714
L17: 31 | M17: 31.106957 | N17: 5.3330435
L18: 32 | M18: 33.2468 | N18: 5.1798
L19: 33 | M19: 31.452222 | N19: 5.0353333 | P19: Row Labels | Q19: Average of Charges
L20: 34 | M20: 31.034426 | N20: 5.3554098 | P20: 18 | Q20: 6611.7447
L21: 35 | M21: 30.4695 | N21: 5.14525 | P21: 19 | Q21: 9677.6395
L22: 36 | M22: 29.481905 | N22: 9.0571429 | P22: 20 | Q22: 7411.8276
L23: 37 | M23: 30.131538 | N23: 5.2648077 | P23: 21 | Q23: 5215.0233
L24: 38 | M24: 28.330909 | N24: 5.2577273 | P24: 22 | Q24: 9806.6538
L25: 39 | M25: 30.269535 | N25: 5.2916279 | P25: 23 | Q25: 11093.4
L26: 40 | M26: 31.188704 | N26: 5.1522222 | P26: 24 | Q26: 9765.9565
L27: 41 | M27: 29.936038 | N27: 9.4313208 | P27: 25 | Q27: 9185.3333
A28: Row Labels | B28: Sum of Number of Major Surgeries | C28: Average of HBA1C | F28: Average of Charges | G28: Column Labels | L28: 42 | M28: 30.411702 | N28: 5.2017021 | P28: 26 | Q28: 5921.0227
A29: No | B29: 1417 | C29: 6.6704427 | F29: Row Labels | G29: Tier - 1 | H29: Tier - 2 | I29: Tier - 3 | J29: Grand Total | L29: 43 | M29: 32.305 | N29: 5.2442 | P29: 27 | Q29: 11846.647
A30: Yes | B30: 162 | C30: 5.1876389 | F30: R1011 | G30: 33081.853 | H30: 18965.034 | I30: 9250.8571 | J30: 19447.758 | L30: 44 | M30: 30.244706 | N30: 9.2566667 | P30: 28 | Q30: 9220.3036
A31: Grand Total | B31: 1579 | C31: 6.5789979 | F31: R1012 | G31: 26111.921 | H31: 10334.752 | I31: 10180.422 | J31: 12016.948 | L31: 45 | M31: 30.940698 | N31: 5.552093 | P31: 29 | Q31: 9915.2642
F32: R1013 | G32: 31328.642 | H32: 8439.4599 | I32: 6891.1765 | J32: 10518.62 | L32: 46 | M32: 30.957193 | N32: 5.3657895 | P32: 30 | Q32: 13788.339
F33: R1014 | G33: 13892.4 | H33: 2396 | I33: 16951 | J33: 13478.615 | L33: 47 | M33: 32.218846 | N33: 8.9861538 | P33: 31 | Q33: 10346.761
F34: R1015 | G34: 21524 | H34: 15676 | I34: 7571.5 | J34: 13949.167 | L34: 48 | M34: 32.017241 | N34: 9.5634483 | P34: 32 | Q34: 14698.66
F35: R1016 | G35: 39869.25 | H35: 16076.417 | I35: 8133.5 | J35: 13589.766 | L35: 49 | M35: 29.947959 | N35: 9.5440816 | P35: 33 | Q35: 11891.622
F36: R1017 | G36: 34071.143 | H36: 11366.125 | I36: 8667.6923 | J36: 14806.556 | L36: 50 | M36: 30.550172 | N36: 5.2236207 | P36: 34 | Q36: 11887.098
F37: R1018 | G37: 33476 | H37: 10140 | I37: 12571.5 | J37: 13273.222 | L37: 51 | M37: 31.368214 | N37: 8.9482143 | P37: 35 | Q37: 10817.8
F38: R1019 | G38: 27622.2 | H38: 8117.2727 | I38: 12707.7 | J38: 13633.769 | L38: 52 | M38: 31.402069 | N38: 9.0668966 | P38: 36 | Q38: 12291.571
F39: R1020 | H39: 6761 | I39: 11717 | J39: 9239 | L39: 53 | M39: 30.20283 | N39: 5.1579245 | P39: 37 | Q39: 16504.231
F40: R1021 | H40: 7668.7234 | I40: 11519.348 | J40: 8933.9286 | L40: 54 | M40: 31.041837 | N40: 9.1555102 | P40: 38 | Q40: 10223.523
F41: R1022 | H41: 10102.333 | I41: 11638.4 | J41: 10650.929 | L41: 55 | M41: 33.014444 | N41: 9.5128889 | P41: 39 | Q41: 14131.302
F42: R1023 | G42: 18262.25 | H42: 13457.625 | I42: 12786 | J42: 13786.632 | L42: 56 | M42: 33.436667 | N42: 5.0845833 | P42: 40 | Q42: 13058.537
...

Sheet DASHBOARD
F3: HEALTH CARE DASHBOARD
B7: Count of Customer ID | C7: Column Labels | H7: Row Labels | I7: Sum of Number of Major Surgeries | J7: Average of HBA1C | M7: Average of Charges | N7: Column Labels | S7: Average of Charges | T7: Column Labels | Y7: Row Labels | Z7: Average of BMI | AA7: Average of HBA1C | AJ7: Row Labels | AK7: Average of Charges
B8: Row Labels | C8: No | D8: Yes | E8: Grand Total | H8: No | I8: 1417 | J8: 6.6704427 | M8: Row Labels | N8: Diabetes | O8: Normal | P8: Prediabetes | Q8: Grand Total | S8: Row Labels | T8: Tier - 1 | U8: Tier - 2 | V8: Tier - 3 | W8: Grand Total | Y8: 18 | Z8: 31.260319 | AA8: 5.1409574 | AJ8: 18 | AK8: 6611.7447
B9: No | C9: 0.65952891 | D9: 0.17301927 | E9: 0.83254818 | H9: Yes | I9: 162 | J9: 5.1876389 | M9: Normal Weight | N9: 12510.304 | O9: 7897.566 | P9: 10390.42 | Q9: 9842.993 | S9: R1011 | T9: 33081.853 | U9: 18965.034 | V9: 9250.8571 | W9: 19447.758 | Y9: 19 | Z9: 29.654535 | AA9: 5.1781395 | AJ9: 19 | AK9: 9677.6395
B10: Yes | C10: 0.13147752 | D10: 0.035974304 | E10: 0.16745182 | H10: Grand Total | I10: 1579 | J10: 6.5789979 | M10: Obesity | N10: 19103.911 | O10: 15140.917 | P10: 15503.249 | Q10: 16612.758 | S10: R1012 | T10: 26111.921 | U10: 10334.752 | V10: 10180.422 | W10: 12016.948 | Y10: 20 | Z10: 28.017931 | AA10: 9.3244828 | AJ10: 20 | AK10: 7411.8276
B11: Grand Total | C11: 0.79100642 | D11: 0.20899358 | E11: 1 | M11: Over Weight | N11: 13887.205 | O11: 10377.135 | P11: 10008.881 | Q11: 11410.287 | S11: R1013 | T11: 31328.642 | U11: 8439.4599 | V11: 6891.1765 | W11: 10518.62 | Y11: 21 | Z11: 29.273953 | AA11: 5.1174419 | AJ11: 21 | AK11: 5215.0233
M12: Under Weight | N12: 7425.3939 | O12: 6911.3171 | P12: 5626.4643 | Q12: 6899.6875 | S12: R1014 | T12: 13892.4 | U12: 2396 | V12: 16951 | W12: 13478.615 | Y12: 22 | Z12: 32.581731 | AA12: 5.2767308 | AJ12: 22 | AK12: 9806.6538
M13: Grand Total | N13: 15974.041 | O13: 12091.205 | P13: 12691.465 | Q13: 13530.407 | S13: R1015 | T13: 21524 | U13: 15676 | V13: 7571.5 | W13: 13949.167 | Y13: 23 | Z13: 30.8296 | AA13: 5.1892 | AJ13: 23 | AK13: 11093.4
S14: R1016 | T14: 39869.25 | U14: 16076.417 | V14: 8133.5 | W14: 13589.766 | Y14: 24 | Z14: 29.017826 | AA14: 5.1626087 | AJ14: 24 | AK14: 9765.9565
S15: R1017 | T15: 34071.143 | U15: 11366.125 | V15: 8667.6923 | W15: 14806.556 | Y15: 25 | Z15: 30.344035 | AA15: 5.2589474 | AJ15: 25 | AK15: 9185.3333
S16: R1018 | T16: 33476 | U16: 10140 | V16: 12571.5 | W16: 13273.222 | Y16: 26 | Z16: 30.441818 | AA16: 5.1029545 | AJ16: 26 | AK16: 5921.0227
S17: R1019 | T17: 27622.2 | U17: 8117.2727 | V17: 12707.7 | W17: 13633.769 | Y17: 27 | Z17: 30.316667 | AA17: 4.9407843 | AJ17: 27 | AK17: 11846.647
S18: R1020 | U18: 6761 | V18: 11717 | W18: 9239 | Y18: 28 | Z18: 31.029464 | AA18: 5.2207143 | AJ18: 28 | AK18: 9220.3036
S19: R1021 | U19: 7668.7234 | V19: 11519.348 | W19: 8933.9286 | Y19: 29 | Z19: 30.763208 | AA19: 5.2043396 | AJ19: 29 | AK19: 9915.2642
S20: R1022 | U20: 10102.333 | V20: 11638.4 | W20: 10650.929 | Y20: 30 | Z20: 33.517857 | AA20: 5.1835714 | AJ20: 30 | AK20: 13788.339
S21: R1023 | T21: 18262.25 | U21: 13457.625 | V21: 12786 | W21: 13786.632 | Y21: 31 | Z21: 31.106957 | AA21: 5.3330435 | AJ21: 31 | AK21: 10346.761
S22: R1024 | T22: 32732.714 | U22: 10174.9 | V22: 13361.472 | W22: 12865.688 | Y22: 32 | Z22: 33.2468 | AA22: 5.1798 | AJ22: 32 | AK22: 14698.66
S23: R1025 | U23: 6886.4737 | V23: 10510.81 | W23: 8789.25 | Y23: 33 | Z23: 31.452222 | AA23: 5.0353333 | AJ23: 33 | AK23: 11891.622
S24: R1026 | T24: 18710.4 | U24: 11920.095 | V24: 12297.378 | W24: 12490.464 | Y24: 34 | Z24: 31.034426 | AA24: 5.3554098 | AJ24: 34 | AK24: 11887.098
S25: UNKNOWN | T25: 20997 | W25: 20997 | Y25: 35 | Z25: 30.4695 | AA25: 5.14525 | AJ25: 35 | AK25: 10817.8
S26: Grand Total | T26: 30129.701 | U26: 11865.759 | V26: 9462.7504 | W26: 13530.407 | Y26: 36 | Z26: 29.481905 | AA26: 9.0571429 | AJ26: 36 | AK26: 12291.571
Y27: 37 | Z27: 30.131538 | AA27: 5.2648077 | AJ27: 37 | AK27: 16504.231
Y28: 38 | Z28: 28.330909 | AA28: 5.2577273 | AJ28: 38 | AK28: 10223.523
Y29: 39 | Z29: 30.269535 | AA29: 5.2916279 | AJ29: 39 | AK29: 14131.302
Y30: 40 | Z30: 31.188704 | AA30: 5.1522222 | AJ30: 40 | AK30: 13058.537
Y31: 41 | Z31: 29.936038 | AA31: 9.4313208 | AJ31: 41 | AK31: 11965.792
Y32: 42 | Z32: 30.411702 | AA32: 5.2017021 | AJ32: 42 | AK32: 13180.957
Y33: 43 | Z33: 32.305 | AA33: 5.2442 | AJ33: 43 | AK33: 17981.12
Y34: 44 | Z34: 30.244706 | AA34: 9.2566667 | AJ34: 44 | AK34: 15162.49
Y35: 45 | Z35: 30.940698 | AA35: 5.552093 | AJ35: 45 | AK35: 15183.628
Y36: 46 | Z36: 30.957193 | AA36: 5.3657895 | AJ36: 46 | AK36: 17592.947
Y37: 47 | Z37: 32.218846 | AA37: 8.9861538 | AJ37: 47 | AK37: 19058.885
Y38: 48 | Z38: 32.017241 | AA38: 9.5634483 | AJ38: 48 | AK38: 15254.293
... Y55: 65 | Z55: 26.89 | AA55: 9.86 | AJ55: 65 | AK55: 29331
Y56: Grand Total | Z56: 30.972685 | AA56: 6.5789979 | AJ56: Grand Total | AK56: 13530.407
